Відповідь: **ні, не виконається**:

```js run
new Promise(function(resolve, reject) {
  setTimeout(() => {
    throw new Error("Whoops!");
  }, 1000);
}).catch(alert);
```
Як було сказано в главі, тут присутній "прихований `try..catch`" навколо коду функції. Тому обробляються усі синхронні помилки.

У цьому прикладі помилка генерується не по ходу виконання коду, а пізніше. Тому проміс не може обробити її.
